Workbook

Sheet Dashboard
B2: Task Status | C2: =Lists!$D$2 -> Brenda C | D2: =Lists!$D$3 -> Brian B | E2: =Lists!$D$4 -> Cliff N | F2: =Lists!$D$6 -> Evans W | G2: =Lists!$D$7 -> Irine M | H2: =Lists!$D$9 -> Joel M | I2: =Lists!$D$10 -> Ken W | J2: =Lists!$D$11 -> Sheilla W | K2: =Lists!$D$5 -> Duncan M | L2: =Lists!$D$8 -> Ivy N | M2: =Lists!$D$13 -> Susan B | N2: =Lists!$D$12 -> Solomon O | Q2: Total | R2: %
B4: =Lists!$B2 -> Done | C4: =COUNTIFS('Task Tracker'!$F:$F,Dashboard!C$2,'Task Tracker'!$D:$D,Dashboard!$B4) -> 31 | D4: =COUNTIFS('Task Tracker'!$F:$F,Dashboard!D$2,'Task Tracker'!$D:$D,Dashboard!$B4) -> 28 | E4: =COUNTIFS('Task Tracker'!$F:$F,Dashboard!E$2,'Task Tracker'!$D:$D,Dashboard!$B4) -> 26 | F4: =COUNTIFS('Task Tracker'!$F:$F,Dashboard!F$2,'Task Tracker'!$D:$D,Dashboard!$B4) -> 12 | G4: =COUNTIFS('Task Tracker'!$F:$F,Dashboard!G$2,'Task Tracker'!$D:$D,Dashboard!$B4) -> 26 | H4: =COUNTIFS('Task Tracker'!$F:$F,Dashboard!H$2,'Task Tracker'!$D:$D,Dashboard!$B4) -> 24 | I4: =COUNTIFS('Task Tracker'!$F:$F,Dashboard!I$2,'Task Tracker'!$D:$D,Dashboard!$B4) -> 32 | J4: =COUNTIFS('Task Tracker'!$F:$F,Dashboard!J$2,'Task Tracker'!$D:$D,Dashboard!$B4) -> 26 | ... O4: =COUNTIFS('Task Tracker'!$F:$F,Dashboard!O$2,'Task Tracker'!$D:$D,Dashboard!$B4) -> 0 | Q4: =SUM(C4:P4) -> 325 | R4: =Q4/$Q$9 -> 0.84635417
B5: =Lists!$B3 -> Ongoing | C5: =COUNTIFS('Task Tracker'!$F:$F,Dashboard!C$2,'Task Tracker'!$D:$D,Dashboard!$B5) -> 7 | D5: =COUNTIFS('Task Tracker'!$F:$F,Dashboard!D$2,'Task Tracker'!$D:$D,Dashboard!$B5) -> 3 | E5: =COUNTIFS('Task Tracker'!$F:$F,Dashboard!E$2,'Task Tracker'!$D:$D,Dashboard!$B5) -> 6 | F5: =COUNTIFS('Task Tracker'!$F:$F,Dashboard!F$2,'Task Tracker'!$D:$D,Dashboard!$B5) -> 2 | G5: =COUNTIFS('Task Tracker'!$F:$F,Dashboard!G$2,'Task Tracker'!$D:$D,Dashboard!$B5) -> 2 | H5: =COUNTIFS('Task Tracker'!$F:$F,Dashboard!H$2,'Task Tracker'!$D:$D,Dashboard!$B5) -> 3 | I5: =COUNTIFS('Task Tracker'!$F:$F,Dashboard!I$2,'Task Tracker'!$D:$D,Dashboard!$B5) -> 1 | J5: =COUNTIFS('Task Tracker'!$F:$F,Dashboard!J$2,'Task Tracker'!$D:$D,Dashboard!$B5) -> 2 | ... O5: =COUNTIFS('Task Tracker'!$F:$F,Dashboard!O$2,'Task Tracker'!$D:$D,Dashboard!$B5) -> 0 | Q5: =SUM(C5:P5) -> 38 | R5: =Q5/$Q$9 -> 0.098958333
B6: =Lists!$B4 -> Pending | C6: =COUNTIFS('Task Tracker'!$F:$F,Dashboard!C$2,'Task Tracker'!$D:$D,Dashboard!$B6) -> 0 | D6: =COUNTIFS('Task Tracker'!$F:$F,Dashboard!D$2,'Task Tracker'!$D:$D,Dashboard!$B6) -> 0 | E6: =COUNTIFS('Task Tracker'!$F:$F,Dashboard!E$2,'Task Tracker'!$D:$D,Dashboard!$B6) -> 0 | F6: =COUNTIFS('Task Tracker'!$F:$F,Dashboard!F$2,'Task Tracker'!$D:$D,Dashboard!$B6) -> 1 | G6: =COUNTIFS('Task Tracker'!$F:$F,Dashboard!G$2,'Task Tracker'!$D:$D,Dashboard!$B6) -> 0 | H6: =COUNTIFS('Task Tracker'!$F:$F,Dashboard!H$2,'Task Tracker'!$D:$D,Dashboard!$B6) -> 0 | I6: =COUNTIFS('Task Tracker'!$F:$F,Dashboard!I$2,'Task Tracker'!$D:$D,Dashboard!$B6) -> 0 | J6: =COUNTIFS('Task Tracker'!$F:$F,Dashboard!J$2,'Task Tracker'!$D:$D,Dashboard!$B6) -> 0 | ... O6: =COUNTIFS('Task Tracker'!$F:$F,Dashboard!O$2,'Task Tracker'!$D:$D,Dashboard!$B6) -> 0 | Q6: =SUM(C6:P6) -> 3 | R6: =Q6/$Q$9 -> 0.0078125
B7: =Lists!$B5 -> Not started | C7: =COUNTIFS('Task Tracker'!$F:$F,Dashboard!C$2,'Task Tracker'!$D:$D,Dashboard!$B7) -> 1 | D7: =COUNTIFS('Task Tracker'!$F:$F,Dashboard!D$2,'Task Tracker'!$D:$D,Dashboard!$B7) -> 1 | E7: =COUNTIFS('Task Tracker'!$F:$F,Dashboard!E$2,'Task Tracker'!$D:$D,Dashboard!$B7) -> 1 | F7: =COUNTIFS('Task Tracker'!$F:$F,Dashboard!F$2,'Task Tracker'!$D:$D,Dashboard!$B7) -> 1 | G7: =COUNTIFS('Task Tracker'!$F:$F,Dashboard!G$2,'Task Tracker'!$D:$D,Dashboard!$B7) -> 0 | H7: =COUNTIFS('Task Tracker'!$F:$F,Dashboard!H$2,'Task Tracker'!$D:$D,Dashboard!$B7) -> 2 | I7: =COUNTIFS('Task Tracker'!$F:$F,Dashboard!I$2,'Task Tracker'!$D:$D,Dashboard!$B7) -> 0 | J7: =COUNTIFS('Task Tracker'!$F:$F,Dashboard!J$2,'Task Tracker'!$D:$D,Dashboard!$B7) -> 0 | ... O7: =COUNTIFS('Task Tracker'!$F:$F,Dashboard!O$2,'Task Tracker'!$D:$D,Dashboard!$B7) -> 0 | Q7: =SUM(C7:P7) -> 6 | R7: =Q7/$Q$9 -> 0.015625
B8: =Lists!$B6 -> Dropped | C8: =COUNTIFS('Task Tracker'!$F:$F,Dashboard!C$2,'Task Tracker'!$D:$D,Dashboard!$B8) -> 4 | D8: =COUNTIFS('Task Tracker'!$F:$F,Dashboard!D$2,'Task Tracker'!$D:$D,Dashboard!$B8) -> 0 | E8: =COUNTIFS('Task Tracker'!$F:$F,Dashboard!E$2,'Task Tracker'!$D:$D,Dashboard!$B8) -> 0 | F8: =COUNTIFS('Task Tracker'!$F:$F,Dashboard!F$2,'Task Tracker'!$D:$D,Dashboard!$B8) -> 4 | G8: =COUNTIFS('Task Tracker'!$F:$F,Dashboard!G$2,'Task Tracker'!$D:$D,Dashboard!$B8) -> 0 | H8: =COUNTIFS('Task Tracker'!$F:$F,Dashboard!H$2,'Task Tracker'!$D:$D,Dashboard!$B8) -> 0 | I8: =COUNTIFS('Task Tracker'!$F:$F,Dashboard!I$2,'Task Tracker'!$D:$D,Dashboard!$B8) -> 1 | J8: =COUNTIFS('Task Tracker'!$F:$F,Dashboard!J$2,'Task Tracker'!$D:$D,Dashboard!$B8) -> 0 | ... O8: =COUNTIFS('Task Tracker'!$F:$F,Dashboard!O$2,'Task Tracker'!$D:$D,Dashboard!$B8) -> 0 | Q8: =SUM(C8:P8) -> 12 | R8: =Q8/$Q$9 -> 0.03125
B9: Total Tasks | C9: =SUM(C4:C8) -> 43 | D9: =SUM(D4:D8) -> 32 | E9: =SUM(E4:E8) -> 33 | F9: =SUM(F4:F8) -> 20 | G9: =SUM(G4:G8) -> 28 | H9: =SUM(H4:H8) -> 29 | I9: =SUM(I4:I8) -> 34 | J9: =SUM(J4:J8) -> 28 | ... O9: =SUM(O4:O8) -> 0 | Q9: =SUM(Q4:Q8) -> 384 | R9: =SUM(R4:R8) -> 1
B10: Count | C10: =COUNTIF('Task Tracker'!$F:$F,Dashboard!C$2) -> 43 | D10: =COUNTIF('Task Tracker'!$F:$F,Dashboard!D$2) -> 32 | E10: =COUNTIF('Task Tracker'!$F:$F,Dashboard!E$2) -> 33 | F10: =COUNTIF('Task Tracker'!$F:$F,Dashboard!F$2) -> 20 | G10: =COUNTIF('Task Tracker'!$F:$F,Dashboard!G$2) -> 28 | H10: =COUNTIF('Task Tracker'!$F:$F,Dashboard!H$2) -> 29 | I10: =COUNTIF('Task Tracker'!$F:$F,Dashboard!I$2) -> 34 | J10: =COUNTIF('Task Tracker'!$F:$F,Dashboard!J$2) -> 28 | ... O10: =COUNTIF('Task Tracker'!$F:$F,Dashboard!O$2) -> 0 | Q10: =SUM(C10:P10) -> 384
B11: Check | C11: =C9-C10 -> 0 | D11: =D9-D10 -> 0 | E11: =E9-E10 -> 0 | F11: =F9-F10 -> 0 | G11: =G9-G10 -> 0 | H11: =H9-H10 -> 0 | I11: =I9-I10 -> 0 | J11: =J9-J10 -> 0 | ... O11: =O9-O10 -> 0 | Q11: =Q9-Q10 -> 0

Sheet Task Tracker
A1: Project/ Client/ Investor | B1: Action Point | C1: Source | D1: Status | E1: Deadline | F1: Owner | G1: Assist | H1: Notes
A2: 02 February - 06 February 2026
A3: Sunset Diani Beach | B3: Send Contract and NDA | D3: Done | E3: 46059 | F3: Ken W
A4: Jarine, Autospring, Transafrica Water | B4: Duncan to coordinate with deal leads | D4: Done | E4: =E3 -> 46059 | F4: Duncan M
A5: Woodhall | B5: Add on tracker | D5: Done | E5: =E4 -> 46059 | F5: Duncan M
A6: Yula | B6: Grant access to VDR and check on the valuation expectations with the founder | D6: Done | E6: =E5 -> 46059 | F6: Cliff N | G6: Sheilla W
A7: Project Nitrogen, Radium, Curious, agate and manganese | B7: Send to Ola Edenbridge | D7: Done | E7: =E6 -> 46059 | F7: Brenda C
A8: Okke | B8: Send Information on ISM Africa | D8: Done | E8: =E7 -> 46059 | F8: Duncan M
A9: Greenforest | B9: Respond to Email revise amount to 500k usd | D9: Done | E9: =E8 -> 46059 | F9: Cliff N
A10: Yongeza | B10: Do a write up on closed deal | D10: Done | E10: =E9 -> 46059 | F10: Ivy N
A11: St Brigits hospital | B11: Irine to share deal with Nelly | D11: Done | E11: =E10 -> 46059 | F11: Irine M
A12: Encore medics ltd | B12: Put on tracker | D12: Done | E12: =E11 -> 46059 | F12: Ken W
A13: Eatfresh | B13: Put on tracker | D13: Done | E13: =E12 -> 46059 | F13: Ken W
A14: Women international | B14: Follow up on data | D14: Done | E14: =E13 -> 46059 | F14: Ivy N
A15: Friend,Tunisia | B15: Susan to review | D15: Done | E15: =E14 -> 46059 | F15: Susan B
A16: Kashia | B16: Start on valuation | D16: Done | E16: =E15 -> 46059 | F16: Sheilla W
A17: Jacksos shona | B17: Introduce him to yongeza | D17: Done | E17: =E16 -> 46059 | F17: Cliff N
A18: Tip point | B18: Check if funds were received | D18: Done | E18: =E17 -> 46059 | F18: Duncan M
... A37: PURA | B37: Susan to update the teaser to mention that they are open to both debt and equity. | D37: Done | E37: =E36 -> 46059 | F37: Susan B
A38: Spice world | B38: Cliff to follow up on the engagement contract. Susan to add the Tz entity to the live deal tracker | D38: Done | E38: =E37 -> 46059 | F38: Cliff N | H38: Pending retainer pyt
A39: Tripple F | B39: Client to share the correct set of accounts before NC starts on the assignments | D39: Done | E39: =E38 -> 46059 | F39: Ken W | H39: Not progressing with deal
A40: Tigoni | B40: follow up with client to provide data | D40: Done | E40: =E39 -> 46059 | F40: Brian B
A41: Sotik Assignment | B41: Brenda is supposed to travel to Sotik in the 2nd week of Feb | D41: Dropped | E41: =E40 -> 46059 | F41: Brenda C | H41: followed up on email
A42: MCB: | B42: DM to follow up with Burak on the arrangements | D42: Done | E42: =E41 -> 46059 | F42: Duncan M
A43: CREAN | B43: follow up with the client to pay retainer fees on the IM | D43: Done | E43: =E42 -> 46059 | F43: Sheilla W
A44: Valley Hospital: | B44: check with Enko if they can fund them | D44: Done | E44: =E43 -> 46059 | F44: Sheilla W
A45: South B: | B45: follow up on whether the payment has been made | D45: Done | E45: =E44 -> 46059 | F45: Sheilla W
A46: Crown Healthcare: | B46: follow up on closure of the transaction | D46: Done | E46: =E45 -> 46059 | F46: Sheilla W
A47: Africa50: | B47: Follow up | D47: Done | E47: =E46 -> 46059 | F47: Duncan M
A48: Vicky | B48: Send FTG to Vicky from South Africa | D48: Done | E48: =E47 -> 46059 | F48: Duncan M
A49: Sealtowers: | B49: Seek update form Axian | D49: Done | E49: =E48 -> 46059 | F49: Duncan M
A50: KDL: | B50: reach out for 2025 number. Follow up with Kevin Kuria Absa and KCB | D50: Done | E50: =E49 -> 46059 | F50: Duncan M
A51: BB Finance: | B51: Follow up for their feedback on Edenbridge | D51: Done | E51: =E50 -> 46059 | F51: Brenda C
A52: NWH: | B52: Update NWH IM and send it to Dr. Thenya | D52: Done | E52: =E51 -> 46059 | F52: Duncan M
A53: Double den | B53: KCB on double den | D53: Done | E53: =E52 -> 46059 | F53: Duncan M
A54: Timeless Timber: | B54: Susan to add deal on the tracker | D54: Done | E54: =E53 -> 46059 | F54: Susan B
A58: 09 February - 13 February 2026
A59: Enat Bank TOR | B59: Ken and Duncan to coordinate | D59: Dropped | E59: 46066 | F59: Duncan M | G59: Ken W | H59: The Ethiopian company did not win the bid
A60: Jarine | B60: Share Management Accounts | D60: Done | E60: =E59 -> 46066 | F60: Brian B
A61: So Pure | B61: Share data list | D61: Done | E61: =E60 -> 46066 | F61: Susan B
...

Sheet Lists
B1: Status | D1: Deal Lead | F1: Source
B2: Done | D2: Brenda C | F2: Monday Meeting
B3: Ongoing | D3: Brian B | F3: WhatsApp
B4: Pending | D4: Cliff N | F4: Email
B5: Not started | D5: Duncan M | F5: Verbal
B6: Dropped | D6: Evans W | F6: Other
D7: Irine M
D8: Ivy N
D9: Joel M
D10: Ken W
D11: Sheilla W
D12: Solomon O
D13: Susan B
